Workbook

Sheet 00_HUONG_DAN_SU_DUNG
B2: HƯỚNG DẪN QUY CHUẨN MẪU: QUẢN LÝ KHỐI LƯỢNG BOQ & KIỂM SOÁT ĐẶT HÀNG VẬT TƯ
B3: Hệ thống Quản lý Dự án & Kiểm soát Chi phí Cơ Điện / Xây dựng (xBOSS Standard Template)
B5: I. 4 NGUYÊN TẮC CỐT LÕI CỦA BIỂU MẪU BOQ
B6: Thuật ngữ / Cột | C6: Vị trí cột | D6: Ý nghĩa nghiệp vụ & Quy định bắt buộc
B7: 1. Mã BOQ là DUY NHẤT (Unique Key) | C7: Cột A | D7: Mỗi chủng loại vật tư / công tác bắt buộc phải có một Mã BOQ duy nhất toàn dự án. Mã này được dùng xuyên suốt để truy xuất, lập đơn đặt hàng vật tư (PO/PR), xuất kho, và nghiệm thu thanh toán.
B8: 2. Khối lượng BOQ (Dự toán ban đầu) | C8: Cột F | D8: Khối lượng theo hồ sơ trúng thầu / Phụ lục hợp đồng đã ký kết giữa Nhà thầu và Chủ đầu tư. Đây là ngân sách trần ban đầu được phê duyệt.
B9: 3. Khối lượng Định mức (Bản vẽ Shop) | C9: Cột G | D9: Khối lượng thực tế do Kỹ sư công trường / Thầu phụ bóc tách chi tiết từ bản vẽ thi công (Shop drawings) đã được phê duyệt.
B10: 4. Chênh lệch & Kiểm soát Đặt hàng | C10: Cột H, J, K | D10: Công thức: [Chênh lệch] = [Khối lượng BOQ] - [Khối lượng Định mức]. • Nếu >= 0: Cho phép đặt hàng (<= Định mức bóc tách). • Nếu < 0: CHẶN ĐẶT HÀNG NGAY LẬP TỨC. Yêu cầu làm hồ sơ bảo vệ khối lượng -> QS xác nhận -> Duyệt sửa BOQ mới mở quyền đặt hàng.
B12: II. QUY TRÌNH 5 BƯỚC KIỂM SOÁT ĐẶT HÀNG VẬT TƯ (PROCUREMENT CONTROL)
B13: Bước thực hiện | C13: Người chịu trách nhiệm | D13: Nội dung thực hiện chi tiết
B14: Bước 1: Khởi tạo BOQ Dự toán | C14: Phòng QS | D14: Nhập danh mục công tác, mã BOQ và Khối lượng BOQ (Cột F) từ Hợp đồng.
B15: Bước 2: Bóc tách bản vẽ Shop | C15: Kỹ sư / Thầu phụ | D15: Cập nhật Khối lượng Định mức thực tế (Cột G) sau khi bản vẽ Shop Drawing được duyệt.
B16: Bước 3: Tự động kiểm tra Chênh lệch | C16: Hệ thống Excel | D16: Cột H tự động tính Chênh lệch = F - G. Cột J tự động phân loại [OK] hoặc [CHẶN].
B17: Bước 4: Xử lý Vượt Định mức (< 0) | C17: Kỹ sư & QS | D17: Với các mã bị CHẶN (< 0), Kỹ sư lập phiếu giải trình nguyên nhân sai lệch -> QS kiểm tra hiện trường/bản vẽ -> Trình CĐT/Ban QLDA phê duyệt bổ sung BOQ (Variation Order).
B18: Bước 5: Cấp phát & Đặt hàng (PO) | C18: Phòng Mua hàng (Procurement) | D18: Chỉ phát hành Đơn đặt hàng (PO/PR) cho các mã có trạng thái [OK] với số lượng tối đa không vượt quá Khối lượng Định mức (Cột G).
B20: III. QUY ƯỚC MÀU SẮC TRÊN BIỂU MẪU (COLOR LEGEND)
B21: Màu Xanh lá (Green) | C21: Chênh lệch >= 0 (Định mức <= BOQ) | D21: ✅ OK - Cho phép đặt hàng theo định mức bóc tách.
B22: Màu Đỏ/Hồng (Red) | C22: Chênh lệch < 0 (Định mức > BOQ) | D22: ❌ CHẶN ĐẶT HÀNG - Vượt dự toán, bắt buộc QS duyệt sửa BOQ.
B23: Màu Vàng (Yellow) | C23: Chưa nhập Cột G (Định mức trống) | D23: ⚠️ Cảnh báo Kỹ sư / Thầu phụ cần hoàn thành bóc tách bản vẽ.

Sheet 00_DASHBOARD_KIEM_SOAT
B2: BẢNG ĐIỀU KHIỂN & KIỂM SOÁT KHỐI LƯỢNG BOQ - ĐẶT HÀNG VẬT TƯ THÁP A
B3: Dự án: BD1.6 - TT AVIO | Gói thầu: Hệ thống Cơ điện ACMV | Nguyên tắc: Mã BOQ duy nhất
B5: I. TỔNG HỢP KIỂM SOÁT ĐỊNH MỨC & ĐẶT HÀNG
B6: Chỉ tiêu kiểm soát | C6: Số lượng mã BOQ | D6: Tỷ lệ (%) | E6: Trạng thái kiểm soát vật tư
B7: Tổng số hạng mục / mã BOQ quản lý | C7: =COUNTA('Data-BOQ'!A7:A883) | D7: 100% | E7: Mã BOQ duy nhất toàn dự án
B8: 1. Đã bóc tách định mức (Khối lượng thực tế bản vẽ) | C8: =COUNT('Data-BOQ'!G7:G883) | D8: =C8/C7 | E8: Kỹ sư/Thầu phụ đã cập nhật
B9: - ✅ Hợp lệ / Đủ điều kiện đặt hàng (Chênh lệch >= 0) | C9: =COUNTIFS('Data-BOQ'!H7:H883, ">=0", 'Data-BOQ'!G7:G883, "<>""") | D9: =C9/C7 | E9: ✅ CHO PHÉP ĐẶT HÀNG (<= Định mức)
B10: - ❌ Vượt định mức so với BOQ (Chênh lệch < 0) | C10: =COUNTIF('Data-BOQ'!H7:H883, "<0") | D10: =C10/C7 | E10: ❌ CHẶN ĐẶT HÀNG (Cần QS bảo vệ & sửa BOQ)
B11: 2. ⚠️ Chưa bóc tách định mức (Cột định mức trống) | C11: =COUNTBLANK('Data-BOQ'!G10:G883) | D11: =C11/C7 | E11: ⚠️ Cần kỹ sư/thầu phụ bóc tách gấp
B14: II. QUY TRÌNH & NGUYÊN TẮC KIỂM SOÁT ĐẶT HÀNG
B15: 1. Mã BOQ: | C15: Mã BOQ là DUY NHẤT. Mọi phiếu xuất kho, đơn đặt hàng (PO/PR), nghiệm thu thanh toán đều phải dẫn chiếu đúng Mã BOQ.
B16: 2. Khối lượng BOQ Tháp A: | C16: Khối lượng dự toán ban đầu theo hồ sơ trúng thầu / Hợp đồng đã ký với Chủ đầu tư.
B17: 3. Khối lượng Định mức Tháp A: | C17: Khối lượng thực tế do Kỹ sư công trường / Thầu phụ bóc tách chi tiết từ bản vẽ thi công (Shop drawing) đã phê duyệt.
B18: 4. Chênh lệch Định mức: | C18: Công thức: [Chênh lệch] = [Khối lượng BOQ Tháp A] - [Khối lượng Định mức Tháp A].
B19: 5. Kiểm soát đặt hàng (>= 0): | C19: Nếu Chênh lệch >= 0 (Định mức thực tế <= BOQ dự toán): ĐỦ ĐIỀU KIỆN ĐẶT HÀNG. Đặt hàng tối đa bằng Khối lượng Định mức bóc tách.
B20: 6. Kiểm soát đặt hàng (< 0): | C20: Nếu Chênh lệch < 0 (Định mức thực tế > BOQ dự toán): CHẶN ĐẶT HÀNG NGAY LẬP TỨC. Bắt buộc Kỹ sư/Thầu phụ làm hồ sơ bảo vệ khối lượng -> Kỹ sư QS xác nhận nguyên nhân sai lệch -> Trình duyệt phát sinh (VO) và sửa BOQ trước khi phát hành PO mua hàng.
B23: III. DANH SÁCH CÁC MÃ BOQ BỊ VƯỢT ĐỊNH MỨC (CHẶN ĐẶT HÀNG - CẦN QS BẢO VỆ KHỐI LƯỢNG)
A24: STT | B24: Mã BOQ | C24: Mô tả chi tiết | D24: ĐVT | E24: BOQ Tháp A (Dự toán) | F24: Định mức Tháp A (Bản vẽ) | G24: Chênh lệch (Thiếu) | H24: Trạng thái kiểm soát | I24: Hành động yêu cầu
A25: 1 | B25: DHKK-D.I1.4.1 | C25: Ống thoát nước ngưng uPVC Ø21 | D25: m | E25: 11174 | F25: 14883 | G25: -3709 | H25: ❌ CHẶN ĐẶT HÀNG | I25: Vượt 3,709.0 m -> QS bảo vệ khối lượng & sửa BOQ
A26: 2 | B26: DHKK-D.I1.5.2 | C26: Bảo ôn ống nước ngưng Ø21 dày 13mm | D26: m | E26: 5013 | F26: 7964 | G26: -2951 | H26: ❌ CHẶN ĐẶT HÀNG | I26: Vượt 2,951.0 m -> QS bảo vệ khối lượng & sửa BOQ
A27: 3 | B27: DHKK-D.I2.3.7 | C27: Ống gió mềm không cách nhiệt D150 | D27: m | E27: 1976 | F27: 2808 | G27: -832 | H27: ❌ CHẶN ĐẶT HÀNG | I27: Vượt 832.0 m -> QS bảo vệ khối lượng & sửa BOQ
A28: 4 | B28: DHKK-D.I1.5.1 | C28: Bảo ôn ống nước ngưng Ø21 dày 9mm | D28: m | E28: 6159 | F28: 6920 | G28: -761 | H28: ❌ CHẶN ĐẶT HÀNG | I28: Vượt 761.0 m -> QS bảo vệ khối lượng & sửa BOQ
A29: 5 | B29: DHKK-C-I.3.3 | C29: Ống thoát nước ngưng uPVC Ø42 | D29: m | E29: 4410 | F29: 4849 | G29: -439 | H29: ❌ CHẶN ĐẶT HÀNG | I29: Vượt 439.0 m -> QS bảo vệ khối lượng & sửa BOQ
A30: 6 | B30: DHKK-C-I.3.2.3 | C30: Bảo ôn ống nước ngưng Ø42 dày 13mm | D30: m | E30: 4410 | F30: 4849 | G30: -439 | H30: ❌ CHẶN ĐẶT HÀNG | I30: Vượt 439.0 m -> QS bảo vệ khối lượng & sửa BOQ
A31: 7 | B31: DHKK-D.I2.3.6 | C31: Ống gió mềm không cách nhiệt D100 | D31: m | E31: 2964 | F31: 3354 | G31: -390 | H31: ❌ CHẶN ĐẶT HÀNG | I31: Vượt 390.0 m -> QS bảo vệ khối lượng & sửa BOQ
A32: 8 | B32: DHKK-C-III.3.1.0 | C32: Ống gió tole mạ kẽm dày 0.95mm | D32: m2 | E32: 418 | F32: 658 | G32: -240 | H32: ❌ CHẶN ĐẶT HÀNG | I32: Vượt 240.0 m2 -> QS bảo vệ khối lượng & sửa BOQ
A33: 9 | B33: DHKK-B-IV1.3.2.1 | C33: Bảo ôn ống nước ngưng Ø21 dày 9mm | D33: m | E33: 0 | F33: 212 | G33: -212 | H33: ❌ CHẶN ĐẶT HÀNG | I33: Vượt 212.0 m -> QS bảo vệ khối lượng & sửa BOQ
A34: 10 | B34: DHKK-C-II.3.3.0 | C34: Ống gió tole mạ kẽm dày 0.75mm | D34: m2 | E34: 780 | F34: 948 | G34: -168 | H34: ❌ CHẶN ĐẶT HÀNG | I34: Vượt 168.0 m2 -> QS bảo vệ khối lượng & sửa BOQ
A35: 11 | B35: DHKK-D.I2.3.0 | C35: Ống gió tole mạ kẽm dày 0.58mm | D35: m2 | E35: 197 | F35: 324 | G35: -127 | H35: ❌ CHẶN ĐẶT HÀNG | I35: Vượt 127.0 m2 -> QS bảo vệ khối lượng & sửa BOQ
A36: 12 | B36: DHKK-D.I1.6.1 | C36: 4Cx1.5mm2 Cu/PVC | D36: m | E36: 19773 | F36: 19864 | G36: -91 | H36: ❌ CHẶN ĐẶT HÀNG | I36: Vượt 91.0 m -> QS bảo vệ khối lượng & sửa BOQ
... A48: 24 | B48: DHKK-D.I3.1.4 | C48: Miệng louver EAL 300x150 + ISC | D48: Cái | E48: 325 | F48: 338 | G48: -13 | H48: ❌ CHẶN ĐẶT HÀNG | I48: Vượt 13.0 Cái -> QS bảo vệ khối lượng & sửa BOQ

Sheet 02_MAU_BOQ_TRONG
B1: DỰ ÁN: [TÊN DỰ ÁN MỚI]
B2: ĐỊA ĐIỂM: [ĐỊA CHỈ DỰ ÁN]
B3: GÓI THẦU: [TÊN GÓI THẦU / HẠNG MỤC]
B4: BIỂU MẪU: QUẢN LÝ KHỐI LƯỢNG BOQ & ĐỊNH MỨC BÓC TÁCH BẢN VẼ
A6: Mã BOQ (Duy nhất) | B6: STT | C6: MÔ TẢ CÔNG TÁC / VẬT TƯ | D6: Mã/ Quy cách | E6: Đơn vị | F6: KHỐI LƯỢNG BOQ (Dự toán HĐ) | G6: KHỐI LƯỢNG ĐỊNH MỨC (Bản vẽ thi công) | H6: CHÊNH LỆCH ĐỊNH MỨC (= BOQ - Định mức) | I6: GHI CHÚ KỸ THUẬT | J6: KIỂM SOÁT ĐẶT HÀNG (QS DUYỆT) | K6: GỢI Ý HÀNH ĐỘNG / ĐIỀU KIỆN
A7: MEP-01 | B7: I | C7: HỆ THỐNG CƠ ĐIỆN MẪU (VÍ DỤ)
A8: MEP-01.1 | B8: 1 | C8: Thiết bị chính / Phụ kiện mẫu | E8: Bộ
A9: MA-BOQ-001 | B9: 1 | C9: [Nhập tên vật tư / thiết bị mẫu 1] | D9: Cái | E9: Cái | H9: =IF(OR(ISNUMBER(F9),ISNUMBER(G9)),N(F9)-N(G9),"") | J9: =IF(OR(ISNUMBER(F9),ISNUMBER(G9)),IF(ISBLANK(G9),"⚠️ Chưa bóc tách định mức",IF(H9>=0,"✅ OK - Cho phép đặt hàng","❌ CHẶN ĐẶT HÀNG - CẦN BẢO VỆ KL")),"") | K9: =IF(OR(ISNUMBER(F9),ISNUMBER(G9)),IF(ISBLANK(G9),"Kỹ sư/Thầu phụ cần bóc tách KL bản vẽ",IF(H9>=0,"Được đặt hàng tối đa "&G9&" "&E9,"Vượt dự toán "&ABS(H9)&" "&E9&" (QS giải trình & duyệt sửa BOQ)")),"")
A10: MA-BOQ-002 | B10: 2 | C10: [Nhập tên vật tư / thiết bị mẫu 2] | D10: Cái | E10: Cái | H10: =IF(OR(ISNUMBER(F10),ISNUMBER(G10)),N(F10)-N(G10),"") | J10: =IF(OR(ISNUMBER(F10),ISNUMBER(G10)),IF(ISBLANK(G10),"⚠️ Chưa bóc tách định mức",IF(H10>=0,"✅ OK - Cho phép đặt hàng","❌ CHẶN ĐẶT HÀNG - CẦN BẢO VỆ KL")),"") | K10: =IF(OR(ISNUMBER(F10),ISNUMBER(G10)),IF(ISBLANK(G10),"Kỹ sư/Thầu phụ cần bóc tách KL bản vẽ",IF(H10>=0,"Được đặt hàng tối đa "&G10&" "&E10,"Vượt dự toán "&ABS(H10)&" "&E10&" (QS giải trình & duyệt sửa BOQ)")),"")
A11: MA-BOQ-003 | B11: 3 | C11: [Nhập tên vật tư / thiết bị mẫu 3] | D11: Cái | E11: Cái | H11: =IF(OR(ISNUMBER(F11),ISNUMBER(G11)),N(F11)-N(G11),"") | J11: =IF(OR(ISNUMBER(F11),ISNUMBER(G11)),IF(ISBLANK(G11),"⚠️ Chưa bóc tách định mức",IF(H11>=0,"✅ OK - Cho phép đặt hàng","❌ CHẶN ĐẶT HÀNG - CẦN BẢO VỆ KL")),"") | K11: =IF(OR(ISNUMBER(F11),ISNUMBER(G11)),IF(ISBLANK(G11),"Kỹ sư/Thầu phụ cần bóc tách KL bản vẽ",IF(H11>=0,"Được đặt hàng tối đa "&G11&" "&E11,"Vượt dự toán "&ABS(H11)&" "&E11&" (QS giải trình & duyệt sửa BOQ)")),"")
A12: MA-BOQ-004 | B12: 4 | C12: [Nhập tên vật tư / thiết bị mẫu 4] | D12: Cái | E12: Cái | H12: =IF(OR(ISNUMBER(F12),ISNUMBER(G12)),N(F12)-N(G12),"") | J12: =IF(OR(ISNUMBER(F12),ISNUMBER(G12)),IF(ISBLANK(G12),"⚠️ Chưa bóc tách định mức",IF(H12>=0,"✅ OK - Cho phép đặt hàng","❌ CHẶN ĐẶT HÀNG - CẦN BẢO VỆ KL")),"") | K12: =IF(OR(ISNUMBER(F12),ISNUMBER(G12)),IF(ISBLANK(G12),"Kỹ sư/Thầu phụ cần bóc tách KL bản vẽ",IF(H12>=0,"Được đặt hàng tối đa "&G12&" "&E12,"Vượt dự toán "&ABS(H12)&" "&E12&" (QS giải trình & duyệt sửa BOQ)")),"")
A13: MA-BOQ-005 | B13: 5 | C13: [Nhập tên vật tư / thiết bị mẫu 5] | D13: Cái | E13: Cái | H13: =IF(OR(ISNUMBER(F13),ISNUMBER(G13)),N(F13)-N(G13),"") | J13: =IF(OR(ISNUMBER(F13),ISNUMBER(G13)),IF(ISBLANK(G13),"⚠️ Chưa bóc tách định mức",IF(H13>=0,"✅ OK - Cho phép đặt hàng","❌ CHẶN ĐẶT HÀNG - CẦN BẢO VỆ KL")),"") | K13: =IF(OR(ISNUMBER(F13),ISNUMBER(G13)),IF(ISBLANK(G13),"Kỹ sư/Thầu phụ cần bóc tách KL bản vẽ",IF(H13>=0,"Được đặt hàng tối đa "&G13&" "&E13,"Vượt dự toán "&ABS(H13)&" "&E13&" (QS giải trình & duyệt sửa BOQ)")),"")
A14: MA-BOQ-006 | B14: 6 | C14: [Nhập tên vật tư / thiết bị mẫu 6] | D14: Cái | E14: Cái | H14: =IF(OR(ISNUMBER(F14),ISNUMBER(G14)),N(F14)-N(G14),"") | J14: =IF(OR(ISNUMBER(F14),ISNUMBER(G14)),IF(ISBLANK(G14),"⚠️ Chưa bóc tách định mức",IF(H14>=0,"✅ OK - Cho phép đặt hàng","❌ CHẶN ĐẶT HÀNG - CẦN BẢO VỆ KL")),"") | K14: =IF(OR(ISNUMBER(F14),ISNUMBER(G14)),IF(ISBLANK(G14),"Kỹ sư/Thầu phụ cần bóc tách KL bản vẽ",IF(H14>=0,"Được đặt hàng tối đa "&G14&" "&E14,"Vượt dự toán "&ABS(H14)&" "&E14&" (QS giải trình & duyệt sửa BOQ)")),"")
A15: MA-BOQ-007 | B15: 7 | C15: [Nhập tên vật tư / thiết bị mẫu 7] | D15: Cái | E15: Cái | H15: =IF(OR(ISNUMBER(F15),ISNUMBER(G15)),N(F15)-N(G15),"") | J15: =IF(OR(ISNUMBER(F15),ISNUMBER(G15)),IF(ISBLANK(G15),"⚠️ Chưa bóc tách định mức",IF(H15>=0,"✅ OK - Cho phép đặt hàng","❌ CHẶN ĐẶT HÀNG - CẦN BẢO VỆ KL")),"") | K15: =IF(OR(ISNUMBER(F15),ISNUMBER(G15)),IF(ISBLANK(G15),"Kỹ sư/Thầu phụ cần bóc tách KL bản vẽ",IF(H15>=0,"Được đặt hàng tối đa "&G15&" "&E15,"Vượt dự toán "&ABS(H15)&" "&E15&" (QS giải trình & duyệt sửa BOQ)")),"")
A16: MA-BOQ-008 | B16: 8 | C16: [Nhập tên vật tư / thiết bị mẫu 8] | D16: Cái | E16: Cái | H16: =IF(OR(ISNUMBER(F16),ISNUMBER(G16)),N(F16)-N(G16),"") | J16: =IF(OR(ISNUMBER(F16),ISNUMBER(G16)),IF(ISBLANK(G16),"⚠️ Chưa bóc tách định mức",IF(H16>=0,"✅ OK - Cho phép đặt hàng","❌ CHẶN ĐẶT HÀNG - CẦN BẢO VỆ KL")),"") | K16: =IF(OR(ISNUMBER(F16),ISNUMBER(G16)),IF(ISBLANK(G16),"Kỹ sư/Thầu phụ cần bóc tách KL bản vẽ",IF(H16>=0,"Được đặt hàng tối đa "&G16&" "&E16,"Vượt dự toán "&ABS(H16)&" "&E16&" (QS giải trình & duyệt sửa BOQ)")),"")
A17: MA-BOQ-009 | B17: 9 | C17: [Nhập tên vật tư / thiết bị mẫu 9] | D17: Cái | E17: Cái | H17: =IF(OR(ISNUMBER(F17),ISNUMBER(G17)),N(F17)-N(G17),"") | J17: =IF(OR(ISNUMBER(F17),ISNUMBER(G17)),IF(ISBLANK(G17),"⚠️ Chưa bóc tách định mức",IF(H17>=0,"✅ OK - Cho phép đặt hàng","❌ CHẶN ĐẶT HÀNG - CẦN BẢO VỆ KL")),"") | K17: =IF(OR(ISNUMBER(F17),ISNUMBER(G17)),IF(ISBLANK(G17),"Kỹ sư/Thầu phụ cần bóc tách KL bản vẽ",IF(H17>=0,"Được đặt hàng tối đa "&G17&" "&E17,"Vượt dự toán "&ABS(H17)&" "&E17&" (QS giải trình & duyệt sửa BOQ)")),"")
A18: MA-BOQ-010 | B18: 10 | C18: [Nhập tên vật tư / thiết bị mẫu 10] | D18: Cái | E18: Cái | H18: =IF(OR(ISNUMBER(F18),ISNUMBER(G18)),N(F18)-N(G18),"") | J18: =IF(OR(ISNUMBER(F18),ISNUMBER(G18)),IF(ISBLANK(G18),"⚠️ Chưa bóc tách định mức",IF(H18>=0,"✅ OK - Cho phép đặt hàng","❌ CHẶN ĐẶT HÀNG - CẦN BẢO VỆ KL")),"") | K18: =IF(OR(ISNUMBER(F18),ISNUMBER(G18)),IF(ISBLANK(G18),"Kỹ sư/Thầu phụ cần bóc tách KL bản vẽ",IF(H18>=0,"Được đặt hàng tối đa "&G18&" "&E18,"Vượt dự toán "&ABS(H18)&" "&E18&" (QS giải trình & duyệt sửa BOQ)")),"")
A19: MA-BOQ-011 | B19: 11 | C19: [Nhập tên vật tư / thiết bị mẫu 11] | D19: Cái | E19: Cái | H19: =IF(OR(ISNUMBER(F19),ISNUMBER(G19)),N(F19)-N(G19),"") | J19: =IF(OR(ISNUMBER(F19),ISNUMBER(G19)),IF(ISBLANK(G19),"⚠️ Chưa bóc tách định mức",IF(H19>=0,"✅ OK - Cho phép đặt hàng","❌ CHẶN ĐẶT HÀNG - CẦN BẢO VỆ KL")),"") | K19: =IF(OR(ISNUMBER(F19),ISNUMBER(G19)),IF(ISBLANK(G19),"Kỹ sư/Thầu phụ cần bóc tách KL bản vẽ",IF(H19>=0,"Được đặt hàng tối đa "&G19&" "&E19,"Vượt dự toán "&ABS(H19)&" "&E19&" (QS giải trình & duyệt sửa BOQ)")),"")
A20: MA-BOQ-012 | B20: 12 | C20: [Nhập tên vật tư / thiết bị mẫu 12] | D20: Cái | E20: Cái | H20: =IF(OR(ISNUMBER(F20),ISNUMBER(G20)),N(F20)-N(G20),"") | J20: =IF(OR(ISNUMBER(F20),ISNUMBER(G20)),IF(ISBLANK(G20),"⚠️ Chưa bóc tách định mức",IF(H20>=0,"✅ OK - Cho phép đặt hàng","❌ CHẶN ĐẶT HÀNG - CẦN BẢO VỆ KL")),"") | K20: =IF(OR(ISNUMBER(F20),ISNUMBER(G20)),IF(ISBLANK(G20),"Kỹ sư/Thầu phụ cần bóc tách KL bản vẽ",IF(H20>=0,"Được đặt hàng tối đa "&G20&" "&E20,"Vượt dự toán "&ABS(H20)&" "&E20&" (QS giải trình & duyệt sửa BOQ)")),"")
... A28: MA-BOQ-020 | B28: 20 | C28: [Nhập tên vật tư / thiết bị mẫu 20] | D28: Cái | E28: Cái | H28: =IF(OR(ISNUMBER(F28),ISNUMBER(G28)),N(F28)-N(G28),"") | J28: =IF(OR(ISNUMBER(F28),ISNUMBER(G28)),IF(ISBLANK(G28),"⚠️ Chưa bóc tách định mức",IF(H28>=0,"✅ OK - Cho phép đặt hàng","❌ CHẶN ĐẶT HÀNG - CẦN BẢO VỆ KL")),"") | K28: =IF(OR(ISNUMBER(F28),ISNUMBER(G28)),IF(ISBLANK(G28),"Kỹ sư/Thầu phụ cần bóc tách KL bản vẽ",IF(H28>=0,"Được đặt hàng tối đa "&G28&" "&E28,"Vượt dự toán "&ABS(H28)&" "&E28&" (QS giải trình & duyệt sửa BOQ)")),"")

Sheet In phiếu xuất
A2: PHIẾU XUẤT KHO
A3: Tên dự án | C3: Khu căn hộ Phúc Lộc Khang
A4: Địa chỉ | C4: Phường Dĩ An, TP. HMC
A5: Tên nhà thầu | C5: An Phát
A6: Hạng mục | C6: Cấp Thoát Nước
A7: Người Xuất
A8: Số | B8: Phiếu 003
A9: Ngày xuất | B9: Tháp | C9: Khu vực | D9: Mã hàng | E9: Tên vật tư | F9: Đơn vị | G9: Số lượng | H9: Số phiếu xuất | I9: Bên nhận | J9: Ghi chú
A10: =IFERROR(__xludf.DUMMYFUNCTION("IFERROR(QUERY('Xuất kho'!A4:J3001, ""select A, B, C, D, E, F, G, H, I where A is not null and H = '""&B8&""'"", 0), ""❌ Không Tìm Thấy PHiếu Xuất"")"),"❌ Không Tìm Thấy PHiếu Xuất")
B41: ĐẠI ĐIỆN BÊN XUẤT | G41: ĐẠI ĐIỆN BÊN NHẬN
B42: Ký ghi rõ họ tên | G42: Ký ghi rõ họ tên

Sheet Data-BOQ
B1: DỰ ÁN: BD1.6 - TT AVIO
B2: ĐỊA ĐIỂM: DĨ AN - BÌNH DƯƠNG
B3: GÓI THẦU: THI CÔNG KẾT CẤU & HOÀN THIỆN NGOÀI
B4: BIỂU: HỆ THỐNG ĐIỀU HÒA KHÔNG KHÍ & THÔNG GIÓ
A6: Mã BOQ | B6: STT | C6: MÔ TẢ | D6: Mã/ vật liệu | E6: Đơn vị | F6: KHỐI LƯỢNG BOQ THÁP A | G6: KHỐI LƯỢNG ĐỊNH MỨC THÁP A | H6: CHÊNH LỆCH ĐỊNH MỨC | I6: GHI CHÚ | J6: KIỂM SOÁT ĐẶT HÀNG (QS DUYỆT) | K6: GỢI Ý HÀNH ĐỘNG / ĐIỀU KIỆN
A7: DHKK-A | B7: A | C7: PHẦN HẦM
A8: DHKK-A.I | B8: I | C8: HỆ THỐNG HÚT KHÓI, CẤP GIÓ TƯƠI
A9: DHKK-A.I.1.0 | B9: 1 | C9: Quạt thông gió | D9: Cái | E9: Cái | H9: =IF(OR(ISNUMBER(F9),ISNUMBER(G9)),N(F9)-N(G9),"") | J9: =IF(OR(ISNUMBER(F9),ISNUMBER(G9)),IF(ISBLANK(G9),"⚠️ Chưa bóc tách định mức",IF(H9>=0,"✅ OK - Cho phép đặt hàng","❌ CHẶN ĐẶT HÀNG - CẦN BẢO VỆ KL")),"") | K9: =IF(OR(ISNUMBER(F9),ISNUMBER(G9)),IF(ISBLANK(G9),"Kỹ sư/Thầu phụ cần bóc tách KL bản vẽ",IF(H9>=0,"Được đặt hàng tối đa "&G9&" "&E9,"Vượt dự toán "&ABS(H9)&" "&E9&" (QS giải trình & duyệt sửa BOQ)")),"")
A10: DHKK-A.I.1.1 | C10: Quạt hút khói kiểu hướng trục nối ống gió ( Quạt chịu nhiệt độ 300 độ trong 1h) EAF-B2-01,02 + Lưu lượng: 5600/8400 l/s + Áp suất: 400/900 Pa | D10: Bộ | E10: Bộ | F10: 2 | G10: =F10 | H10: =IF(OR(ISNUMBER(F10),ISNUMBER(G10)),N(F10)-N(G10),"") | J10: =IF(OR(ISNUMBER(F10),ISNUMBER(G10)),IF(ISBLANK(G10),"⚠️ Chưa bóc tách định mức",IF(H10>=0,"✅ OK - Cho phép đặt hàng","❌ CHẶN ĐẶT HÀNG - CẦN BẢO VỆ KL")),"") | K10: =IF(OR(ISNUMBER(F10),ISNUMBER(G10)),IF(ISBLANK(G10),"Kỹ sư/Thầu phụ cần bóc tách KL bản vẽ",IF(H10>=0,"Được đặt hàng tối đa "&G10&" "&E10,"Vượt dự toán "&ABS(H10)&" "&E10&" (QS giải trình & duyệt sửa BOQ)")),"")
A11: DHKK-A.I.1.2 | C11: Quạt hút khói kiểu hướng trục nối ống gió ( Quạt chịu nhiệt độ 300 độ trong 1h) EAF-B2-03,04 + Lưu lượng: 5600/8400 l/s + Áp suất: 400/900 Pa | D11: Bộ | E11: Bộ | F11: 2 | G11: =F11 | H11: =IF(OR(ISNUMBER(F11),ISNUMBER(G11)),N(F11)-N(G11),"") | J11: =IF(OR(ISNUMBER(F11),ISNUMBER(G11)),IF(ISBLANK(G11),"⚠️ Chưa bóc tách định mức",IF(H11>=0,"✅ OK - Cho phép đặt hàng","❌ CHẶN ĐẶT HÀNG - CẦN BẢO VỆ KL")),"") | K11: =IF(OR(ISNUMBER(F11),ISNUMBER(G11)),IF(ISBLANK(G11),"Kỹ sư/Thầu phụ cần bóc tách KL bản vẽ",IF(H11>=0,"Được đặt hàng tối đa "&G11&" "&E11,"Vượt dự toán "&ABS(H11)&" "&E11&" (QS giải trình & duyệt sửa BOQ)")),"")
A12: DHKK-A.I.1.3 | C12: Quạt hút khói kiểu hướng trục nối ống gió ( Quạt chịu nhiệt độ 300 độ trong 1h) EAF-B2-05,06 + Lưu lượng: 5200/7800 l/s + Áp suất: 400/900 Pa | D12: Bộ | E12: Bộ | F12: 2 | G12: =F12 | H12: =IF(OR(ISNUMBER(F12),ISNUMBER(G12)),N(F12)-N(G12),"") | J12: =IF(OR(ISNUMBER(F12),ISNUMBER(G12)),IF(ISBLANK(G12),"⚠️ Chưa bóc tách định mức",IF(H12>=0,"✅ OK - Cho phép đặt hàng","❌ CHẶN ĐẶT HÀNG - CẦN BẢO VỆ KL")),"") | K12: =IF(OR(ISNUMBER(F12),ISNUMBER(G12)),IF(ISBLANK(G12),"Kỹ sư/Thầu phụ cần bóc tách KL bản vẽ",IF(H12>=0,"Được đặt hàng tối đa "&G12&" "&E12,"Vượt dự toán "&ABS(H12)&" "&E12&" (QS giải trình & duyệt sửa BOQ)")),"")
A13: DHKK-A.I.1.4 | C13: Quạt hút khói kiểu hướng trục nối ống gió ( Quạt chịu nhiệt độ 300 độ trong 1h) EAF-B2-07,08 + Lưu lượng: 7500/11250 l/s + Áp suất: 400/900 Pa | D13: Bộ | E13: Bộ | F13: 0 | G13: =F13 | H13: =IF(OR(ISNUMBER(F13),ISNUMBER(G13)),N(F13)-N(G13),"") | J13: =IF(OR(ISNUMBER(F13),ISNUMBER(G13)),IF(ISBLANK(G13),"⚠️ Chưa bóc tách định mức",IF(H13>=0,"✅ OK - Cho phép đặt hàng","❌ CHẶN ĐẶT HÀNG - CẦN BẢO VỆ KL")),"") | K13: =IF(OR(ISNUMBER(F13),ISNUMBER(G13)),IF(ISBLANK(G13),"Kỹ sư/Thầu phụ cần bóc tách KL bản vẽ",IF(H13>=0,"Được đặt hàng tối đa "&G13&" "&E13,"Vượt dự toán "&ABS(H13)&" "&E13&" (QS giải trình & duyệt sửa BOQ)")),"")
A14: DHKK-A.I.1.5 | C14: Quạt hút khói kiểu hướng trục nối ống gió ( Quạt chịu nhiệt độ 300 độ trong 1h) EAF-B2-09,10 + Lưu lượng: 5400/8100 l/s + Áp suất: 400/900 Pa | D14: Bộ | E14: Bộ | F14: 0 | G14: =F14 | H14: =IF(OR(ISNUMBER(F14),ISNUMBER(G14)),N(F14)-N(G14),"") | J14: =IF(OR(ISNUMBER(F14),ISNUMBER(G14)),IF(ISBLANK(G14),"⚠️ Chưa bóc tách định mức",IF(H14>=0,"✅ OK - Cho phép đặt hàng","❌ CHẶN ĐẶT HÀNG - CẦN BẢO VỆ KL")),"") | K14: =IF(OR(ISNUMBER(F14),ISNUMBER(G14)),IF(ISBLANK(G14),"Kỹ sư/Thầu phụ cần bóc tách KL bản vẽ",IF(H14>=0,"Được đặt hàng tối đa "&G14&" "&E14,"Vượt dự toán "&ABS(H14)&" "&E14&" (QS giải trình & duyệt sửa BOQ)")),"")
A15: DHKK-A.I.1.6 | C15: Quạt cấp khí kiểu hướng trục nối ống gió FAF-B2-01,02 + Lưu lượng: 5600/8400 l/s + Áp suất: 400/900 Pa | D15: Bộ | E15: Bộ | F15: 2 | G15: =F15 | H15: =IF(OR(ISNUMBER(F15),ISNUMBER(G15)),N(F15)-N(G15),"") | J15: =IF(OR(ISNUMBER(F15),ISNUMBER(G15)),IF(ISBLANK(G15),"⚠️ Chưa bóc tách định mức",IF(H15>=0,"✅ OK - Cho phép đặt hàng","❌ CHẶN ĐẶT HÀNG - CẦN BẢO VỆ KL")),"") | K15: =IF(OR(ISNUMBER(F15),ISNUMBER(G15)),IF(ISBLANK(G15),"Kỹ sư/Thầu phụ cần bóc tách KL bản vẽ",IF(H15>=0,"Được đặt hàng tối đa "&G15&" "&E15,"Vượt dự toán "&ABS(H15)&" "&E15&" (QS giải trình & duyệt sửa BOQ)")),"")
A16: DHKK-A.I.1.7 | C16: Quạt cấp khí kiểu hướng trục nối ống gió FAF-B2-03,04 + Lưu lượng: 5600/8400 l/s + Áp suất: 400/900 Pa | D16: Bộ | E16: Bộ | F16: 2 | G16: =F16 | H16: =IF(OR(ISNUMBER(F16),ISNUMBER(G16)),N(F16)-N(G16),"") | J16: =IF(OR(ISNUMBER(F16),ISNUMBER(G16)),IF(ISBLANK(G16),"⚠️ Chưa bóc tách định mức",IF(H16>=0,"✅ OK - Cho phép đặt hàng","❌ CHẶN ĐẶT HÀNG - CẦN BẢO VỆ KL")),"") | K16: =IF(OR(ISNUMBER(F16),ISNUMBER(G16)),IF(ISBLANK(G16),"Kỹ sư/Thầu phụ cần bóc tách KL bản vẽ",IF(H16>=0,"Được đặt hàng tối đa "&G16&" "&E16,"Vượt dự toán "&ABS(H16)&" "&E16&" (QS giải trình & duyệt sửa BOQ)")),"")
A17: DHKK-A.I.1.8 | C17: Quạt cấp khí kiểu hướng trục nối ống gió FAF-B2-05,06 + Lưu lượng: 5200/7800 l/s + Áp suất: 400/900 Pa | D17: Bộ | E17: Bộ | F17: 2 | G17: =F17 | H17: =IF(OR(ISNUMBER(F17),ISNUMBER(G17)),N(F17)-N(G17),"") | J17: =IF(OR(ISNUMBER(F17),ISNUMBER(G17)),IF(ISBLANK(G17),"⚠️ Chưa bóc tách định mức",IF(H17>=0,"✅ OK - Cho phép đặt hàng","❌ CHẶN ĐẶT HÀNG - CẦN BẢO VỆ KL")),"") | K17: =IF(OR(ISNUMBER(F17),ISNUMBER(G17)),IF(ISBLANK(G17),"Kỹ sư/Thầu phụ cần bóc tách KL bản vẽ",IF(H17>=0,"Được đặt hàng tối đa "&G17&" "&E17,"Vượt dự toán "&ABS(H17)&" "&E17&" (QS giải trình & duyệt sửa BOQ)")),"")
A18: DHKK-A.I.1.9 | C18: Quạt cấp khí kiểu hướng trục nối ống gió FAF-B2-07,08 + Lưu lượng: 7500/11250 l/s + Áp suất: 400/900 Pa | D18: Bộ | E18: Bộ | F18: 0 | G18: =F18 | H18: =IF(OR(ISNUMBER(F18),ISNUMBER(G18)),N(F18)-N(G18),"") | J18: =IF(OR(ISNUMBER(F18),ISNUMBER(G18)),IF(ISBLANK(G18),"⚠️ Chưa bóc tách định mức",IF(H18>=0,"✅ OK - Cho phép đặt hàng","❌ CHẶN ĐẶT HÀNG - CẦN BẢO VỆ KL")),"") | K18: =IF(OR(ISNUMBER(F18),ISNUMBER(G18)),IF(ISBLANK(G18),"Kỹ sư/Thầu phụ cần bóc tách KL bản vẽ",IF(H18>=0,"Được đặt hàng tối đa "&G18&" "&E18,"Vượt dự toán "&ABS(H18)&" "&E18&" (QS giải trình & duyệt sửa BOQ)")),"")
A19: DHKK-A.I.1.10 | C19: Quạt cấp khí kiểu hướng trục nối ống gió FAF-B2-09,10 + Lưu lượng: 5400/8100 l/s + Áp suất: 400/900 Pa | D19: Bộ | E19: Bộ | F19: 0 | G19: =F19 | H19: =IF(OR(ISNUMBER(F19),ISNUMBER(G19)),N(F19)-N(G19),"") | J19: =IF(OR(ISNUMBER(F19),ISNUMBER(G19)),IF(ISBLANK(G19),"⚠️ Chưa bóc tách định mức",IF(H19>=0,"✅ OK - Cho phép đặt hàng","❌ CHẶN ĐẶT HÀNG - CẦN BẢO VỆ KL")),"") | K19: =IF(OR(ISNUMBER(F19),ISNUMBER(G19)),IF(ISBLANK(G19),"Kỹ sư/Thầu phụ cần bóc tách KL bản vẽ",IF(H19>=0,"Được đặt hàng tối đa "&G19&" "&E19,"Vượt dự toán "&ABS(H19)&" "&E19&" (QS giải trình & duyệt sửa BOQ)")),"")
A20: DHKK-A.I.1.11 | C20: Quạt hút khói kiểu hướng trục nối ống gió ( Quạt chịu nhiệt độ 300 độ trong 1h) EAF-B1-01,02 + Lưu lượng: 7500/11250 l/s + Áp suất: 400/900 Pa | D20: Bộ | E20: Bộ | F20: 2 | G20: =F20 | H20: =IF(OR(ISNUMBER(F20),ISNUMBER(G20)),N(F20)-N(G20),"") | J20: =IF(OR(ISNUMBER(F20),ISNUMBER(G20)),IF(ISBLANK(G20),"⚠️ Chưa bóc tách định mức",IF(H20>=0,"✅ OK - Cho phép đặt hàng","❌ CHẶN ĐẶT HÀNG - CẦN BẢO VỆ KL")),"") | K20: =IF(OR(ISNUMBER(F20),ISNUMBER(G20)),IF(ISBLANK(G20),"Kỹ sư/Thầu phụ cần bóc tách KL bản vẽ",IF(H20>=0,"Được đặt hàng tối đa "&G20&" "&E20,"Vượt dự toán "&ABS(H20)&" "&E20&" (QS giải trình & duyệt sửa BOQ)")),"")
A21: DHKK-A.I.1.12 | C21: Quạt hút khói kiểu hướng trục nối ống gió ( Quạt chịu nhiệt độ 300 độ trong 1h) EAF-B1-03,04 + Lưu lượng: 8000/12000 l/s + Áp suất: 400/900 Pa | D21: Bộ | E21: Bộ | F21: 2 | G21: =F21 | H21: =IF(OR(ISNUMBER(F21),ISNUMBER(G21)),N(F21)-N(G21),"") | J21: =IF(OR(ISNUMBER(F21),ISNUMBER(G21)),IF(ISBLANK(G21),"⚠️ Chưa bóc tách định mức",IF(H21>=0,"✅ OK - Cho phép đặt hàng","❌ CHẶN ĐẶT HÀNG - CẦN BẢO VỆ KL")),"") | K21: =IF(OR(ISNUMBER(F21),ISNUMBER(G21)),IF(ISBLANK(G21),"Kỹ sư/Thầu phụ cần bóc tách KL bản vẽ",IF(H21>=0,"Được đặt hàng tối đa "&G21&" "&E21,"Vượt dự toán "&ABS(H21)&" "&E21&" (QS giải trình & duyệt sửa BOQ)")),"")
... A44: DHKK-A.I.1.35 | C44: Quạt đảo gắn tường | D44: Bộ | E44: Bộ | F44: 10 | G44: =F44 | H44: =IF(OR(ISNUMBER(F44),ISNUMBER(G44)),N(F44)-N(G44),"") | J44: =IF(OR(ISNUMBER(F44),ISNUMBER(G44)),IF(ISBLANK(G44),"⚠️ Chưa bóc tách định mức",IF(H44>=0,"✅ OK - Cho phép đặt hàng","❌ CHẶN ĐẶT HÀNG - CẦN BẢO VỆ KL")),"") | K44: =IF(OR(ISNUMBER(F44),ISNUMBER(G44)),IF(ISBLANK(G44),"Kỹ sư/Thầu phụ cần bóc tách KL bản vẽ",IF(H44>=0,"Được đặt hàng tối đa "&G44&" "&E44,"Vượt dự toán "&ABS(H44)&" "&E44&" (QS giải trình & duyệt sửa BOQ)")),"")
A45: DHKK-A.I.1.36 | C45: Nối mềm cho quạt | D45: Bộ | E45: Bộ | F45: 14 | G45: =F45 | H45: =IF(OR(ISNUMBER(F45),ISNUMBER(G45)),N(F45)-N(G45),"") | I45: 1 bộ gồm 2 cái | J45: =IF(OR(ISNUMBER(F45),ISNUMBER(G45)),IF(ISBLANK(G45),"⚠️ Chưa bóc tách định mức",IF(H45>=0,"✅ OK - Cho phép đặt hàng","❌ CHẶN ĐẶT HÀNG - CẦN BẢO VỆ KL")),"") | K45: =IF(OR(ISNUMBER(F45),ISNUMBER(G45)),IF(ISBLANK(G45),"Kỹ sư/Thầu phụ cần bóc tách KL bản vẽ",IF(H45>=0,"Được đặt hàng tối đa "&G45&" "&E45,"Vượt dự toán "&ABS(H45)&" "&E45&" (QS giải trình & duyệt sửa BOQ)")),"")
A46: DHKK-A.I.1.37 | C46: Nối mềm chống cháy cho quạt | D46: Bộ | E46: Bộ | F46: 12 | G46: =F46 | H46: =IF(OR(ISNUMBER(F46),ISNUMBER(G46)),N(F46)-N(G46),"") | I46: 1 bộ gồm 2 cái | J46: =IF(OR(ISNUMBER(F46),ISNUMBER(G46)),IF(ISBLANK(G46),"⚠️ Chưa bóc tách định mức",IF(H46>=0,"✅ OK - Cho phép đặt hàng","❌ CHẶN ĐẶT HÀNG - CẦN BẢO VỆ KL")),"") | K46: =IF(OR(ISNUMBER(F46),ISNUMBER(G46)),IF(ISBLANK(G46),"Kỹ sư/Thầu phụ cần bóc tách KL bản vẽ",IF(H46>=0,"Được đặt hàng tối đa "&G46&" "&E46,"Vượt dự toán "&ABS(H46)&" "&E46&" (QS giải trình & duyệt sửa BOQ)")),"")
B48: 2 | C48: Miệng gió, van gió
A49: DHKK-A.I.2.1 | C49: FAG 200x200 kèm OBD | D49: Cái | E49: Cái | F49: 5 | G49: =F49 | H49: =IF(OR(ISNUMBER(F49),ISNUMBER(G49)),N(F49)-N(G49),"") | I49: Miệng gió loại nan bầu dục 1 lớp nan kèm OBD | J49: =IF(OR(ISNUMBER(F49),ISNUMBER(G49)),IF(ISBLANK(G49),"⚠️ Chưa bóc tách định mức",IF(H49>=0,"✅ OK - Cho phép đặt hàng","❌ CHẶN ĐẶT HÀNG - CẦN BẢO VỆ KL")),"") | K49: =IF(OR(ISNUMBER(F49),ISNUMBER(G49)),IF(ISBLANK(G49),"Kỹ sư/Thầu phụ cần bóc tách KL bản vẽ",IF(H49>=0,"Được đặt hàng tối đa "&G49&" "&E49,"Vượt dự toán "&ABS(H49)&" "&E49&" (QS giải trình & duyệt sửa BOQ)")),"")
A50: DHKK-A.I.2.2 | C50: FAG 800x600 kèm OBD | D50: Cái | E50: Cái | F50: 100 | G50: =F50 | H50: =IF(OR(ISNUMBER(F50),ISNUMBER(G50)),N(F50)-N(G50),"") | I50: Miệng gió loại nan bầu dục 1 lớp nan kèm OBD | J50: =IF(OR(ISNUMBER(F50),ISNUMBER(G50)),IF(ISBLANK(G50),"⚠️ Chưa bóc tách định mức",IF(H50>=0,"✅ OK - Cho phép đặt hàng","❌ CHẶN ĐẶT HÀNG - CẦN BẢO VỆ KL")),"") | K50: =IF(OR(ISNUMBER(F50),ISNUMBER(G50)),IF(ISBLANK(G50),"Kỹ sư/Thầu phụ cần bóc tách KL bản vẽ",IF(H50>=0,"Được đặt hàng tối đa "&G50&" "&E50,"Vượt dự toán "&ABS(H50)&" "&E50&" (QS giải trình & duyệt sửa BOQ)")),"")
A51: DHKK-A.I.2.3 | C51: EAG 1200x350 kèm OBD | D51: Cái | E51: Cái | F51: 48 | G51: =F51 | H51: =IF(OR(ISNUMBER(F51),ISNUMBER(G51)),N(F51)-N(G51),"") | I51: Miệng gió loại nan bầu dục 1 lớp nan kèm OBD | J51: =IF(OR(ISNUMBER(F51),ISNUMBER(G51)),IF(ISBLANK(G51),"⚠️ Chưa bóc tách định mức",IF(H51>=0,"✅ OK - Cho phép đặt hàng","❌ CHẶN ĐẶT HÀNG - CẦN BẢO VỆ KL")),"") | K51: =IF(OR(ISNUMBER(F51),ISNUMBER(G51)),IF(ISBLANK(G51),"Kỹ sư/Thầu phụ cần bóc tách KL bản vẽ",IF(H51>=0,"Được đặt hàng tối đa "&G51&" "&E51,"Vượt dự toán "&ABS(H51)&" "&E51&" (QS giải trình & duyệt sửa BOQ)")),"")
A52: DHKK-A.I.2.4 | C52: EAG 1200x400 kèm OBD | D52: Cái | E52: Cái | F52: 48 | G52: =F52 | H52: =IF(OR(ISNUMBER(F52),ISNUMBER(G52)),N(F52)-N(G52),"") | I52: Miệng gió loại nan bầu dục 1 lớp nan kèm OBD | J52: =IF(OR(ISNUMBER(F52),ISNUMBER(G52)),IF(ISBLANK(G52),"⚠️ Chưa bóc tách định mức",IF(H52>=0,"✅ OK - Cho phép đặt hàng","❌ CHẶN ĐẶT HÀNG - CẦN BẢO VỆ KL")),"") | K52: =IF(OR(ISNUMBER(F52),ISNUMBER(G52)),IF(ISBLANK(G52),"Kỹ sư/Thầu phụ cần bóc tách KL bản vẽ",IF(H52>=0,"Được đặt hàng tối đa "&G52&" "&E52,"Vượt dự toán "&ABS(H52)&" "&E52&" (QS giải trình & duyệt sửa BOQ)")),"")
A53: DHKK-A.I.2.5 | C53: EAG 500x500 kèm OBD | D53: Cái | E53: Cái | F53: 0 | G53: =F53 | H53: =IF(OR(ISNUMBER(F53),ISNUMBER(G53)),N(F53)-N(G53),"") | I53: Miệng gió loại nan bầu dục 1 lớp nan kèm OBD | J53: =IF(OR(ISNUMBER(F53),ISNUMBER(G53)),IF(ISBLANK(G53),"⚠️ Chưa bóc tách định mức",IF(H53>=0,"✅ OK - Cho phép đặt hàng","❌ CHẶN ĐẶT HÀNG - CẦN BẢO VỆ KL")),"") | K53: =IF(OR(ISNUMBER(F53),ISNUMBER(G53)),IF(ISBLANK(G53),"Kỹ sư/Thầu phụ cần bóc tách KL bản vẽ",IF(H53>=0,"Được đặt hàng tối đa "&G53&" "&E53,"Vượt dự toán "&ABS(H53)&" "&E53&" (QS giải trình & duyệt sửa BOQ)")),"")
A54: DHKK-A.I.2.6 | C54: EAL 200x150+I.S | D54: Cái | E54: Cái | F54: 1 | G54: =F54 | H54: =IF(OR(ISNUMBER(F54),ISNUMBER(G54)),N(F54)-N(G54),"") | I54: Louver nan Z kèm LCCT | J54: =IF(OR(ISNUMBER(F54),ISNUMBER(G54)),IF(ISBLANK(G54),"⚠️ Chưa bóc tách định mức",IF(H54>=0,"✅ OK - Cho phép đặt hàng","❌ CHẶN ĐẶT HÀNG - CẦN BẢO VỆ KL")),"") | K54: =IF(OR(ISNUMBER(F54),ISNUMBER(G54)),IF(ISBLANK(G54),"Kỹ sư/Thầu phụ cần bóc tách KL bản vẽ",IF(H54>=0,"Được đặt hàng tối đa "&G54&" "&E54,"Vượt dự toán "&ABS(H54)&" "&E54&" (QS giải trình & duyệt sửa BOQ)")),"")
A55: DHKK-A.I.2.7 | C55: FAL 400x200 | D55: Cái | E55: Cái | F55: 4 | G55: =F55 | H55: =IF(OR(ISNUMBER(F55),ISNUMBER(G55)),N(F55)-N(G55),"") | I55: Louver nan Z kèm LCCT | J55: =IF(OR(ISNUMBER(F55),ISNUMBER(G55)),IF(ISBLANK(G55),"⚠️ Chưa bóc tách định mức",IF(H55>=0,"✅ OK - Cho phép đặt hàng","❌ CHẶN ĐẶT HÀNG - CẦN BẢO VỆ KL")),"") | K55: =IF(OR(ISNUMBER(F55),ISNUMBER(G55)),IF(ISBLANK(G55),"Kỹ sư/Thầu phụ cần bóc tách KL bản vẽ",IF(H55>=0,"Được đặt hàng tối đa "&G55&" "&E55,"Vượt dự toán "&ABS(H55)&" "&E55&" (QS giải trình & duyệt sửa BOQ)")),"")
A56: DHKK-A.I.2.8 | C56: FAL 400x400 | D56: Cái | E56: Cái | F56: 10 | G56: =F56 | H56: =IF(OR(ISNUMBER(F56),ISNUMBER(G56)),N(F56)-N(G56),"") | I56: Louver nan Z kèm LCCT | J56: =IF(OR(ISNUMBER(F56),ISNUMBER(G56)),IF(ISBLANK(G56),"⚠️ Chưa bóc tách định mức",IF(H56>=0,"✅ OK - Cho phép đặt hàng","❌ CHẶN ĐẶT HÀNG - CẦN BẢO VỆ KL")),"") | K56: =IF(OR(ISNUMBER(F56),ISNUMBER(G56)),IF(ISBLANK(G56),"Kỹ sư/Thầu phụ cần bóc tách KL bản vẽ",IF(H56>=0,"Được đặt hàng tối đa "&G56&" "&E56,"Vượt dự toán "&ABS(H56)&" "&E56&" (QS giải trình & duyệt sửa BOQ)")),"")
A57: DHKK-A.I.2.9 | C57: FAL 1000x300+I.S | D57: Cái | E57: Cái | F57: 2 | G57: =F57 | H57: =IF(OR(ISNUMBER(F57),ISNUMBER(G57)),N(F57)-N(G57),"") | I57: Louver nan Z kèm LCCT | J57: =IF(OR(ISNUMBER(F57),ISNUMBER(G57)),IF(ISBLANK(G57),"⚠️ Chưa bóc tách định mức",IF(H57>=0,"✅ OK - Cho phép đặt hàng","❌ CHẶN ĐẶT HÀNG - CẦN BẢO VỆ KL")),"") | K57: =IF(OR(ISNUMBER(F57),ISNUMBER(G57)),IF(ISBLANK(G57),"Kỹ sư/Thầu phụ cần bóc tách KL bản vẽ",IF(H57>=0,"Được đặt hàng tối đa "&G57&" "&E57,"Vượt dự toán "&ABS(H57)&" "&E57&" (QS giải trình & duyệt sửa BOQ)")),"")
A58: DHKK-A.I.2.10 | C58: FAL 1000x1000+I.S | D58: Cái | E58: Cái | F58: 1 | G58: =F58 | H58: =IF(OR(ISNUMBER(F58),ISNUMBER(G58)),N(F58)-N(G58),"") | I58: Louver nan Z kèm LCCT | J58: =IF(OR(ISNUMBER(F58),ISNUMBER(G58)),IF(ISBLANK(G58),"⚠️ Chưa bóc tách định mức",IF(H58>=0,"✅ OK - Cho phép đặt hàng","❌ CHẶN ĐẶT HÀNG - CẦN BẢO VỆ KL")),"") | K58: =IF(OR(ISNUMBER(F58),ISNUMBER(G58)),IF(ISBLANK(G58),"Kỹ sư/Thầu phụ cần bóc tách KL bản vẽ",IF(H58>=0,"Được đặt hàng tối đa "&G58&" "&E58,"Vượt dự toán "&ABS(H58)&" "&E58&" (QS giải trình & duyệt sửa BOQ)")),"")
A59: DHKK-A.I.2.11 | C59: FAL 1000x1500+I.S | D59: Cái | E59: Cái | F59: 1 | G59: =F59 | H59: =IF(OR(ISNUMBER(F59),ISNUMBER(G59)),N(F59)-N(G59),"") | I59: Louver nan Z kèm LCCT | J59: =IF(OR(ISNUMBER(F59),ISNUMBER(G59)),IF(ISBLANK(G59),"⚠️ Chưa bóc tách định mức",IF(H59>=0,"✅ OK - Cho phép đặt hàng","❌ CHẶN ĐẶT HÀNG - CẦN BẢO VỆ KL")),"") | K59: =IF(OR(ISNUMBER(F59),ISNUMBER(G59)),IF(ISBLANK(G59),"Kỹ sư/Thầu phụ cần bóc tách KL bản vẽ",IF(H59>=0,"Được đặt hàng tối đa "&G59&" "&E59,"Vượt dự toán "&ABS(H59)&" "&E59&" (QS giải trình & duyệt sửa BOQ)")),"")
A60: DHKK-A.I.2.12 | C60: FAL 1500x1000+I.S | D60: Cái | E60: Cái | F60: 0 | G60: =F60 | H60: =IF(OR(ISNUMBER(F60),ISNUMBER(G60)),N(F60)-N(G60),"") | I60: Louver nan Z kèm LCCT | J60: =IF(OR(ISNUMBER(F60),ISNUMBER(G60)),IF(ISBLANK(G60),"⚠️ Chưa bóc tách định mức",IF(H60>=0,"✅ OK - Cho phép đặt hàng","❌ CHẶN ĐẶT HÀNG - CẦN BẢO VỆ KL")),"") | K60: =IF(OR(ISNUMBER(F60),ISNUMBER(G60)),IF(ISBLANK(G60),"Kỹ sư/Thầu phụ cần bóc tách KL bản vẽ",IF(H60>=0,"Được đặt hàng tối đa "&G60&" "&E60,"Vượt dự toán "&ABS(H60)&" "&E60&" (QS giải trình & duyệt sửa BOQ)")),"")
... A93: DHKK-A.I.2.45 | C93: NRD 1800x600 | D93: Cái | E93: Cái | F93: 0 | G93: =F93 | H93: =IF(OR(ISNUMBER(F93),ISNUMBER(G93)),N(F93)-N(G93),"") | I93: EI60 | J93: =IF(OR(ISNUMBER(F93),ISNUMBER(G93)),IF(ISBLANK(G93),"⚠️ Chưa bóc tách định mức",IF(H93>=0,"✅ OK - Cho phép đặt hàng","❌ CHẶN ĐẶT HÀNG - CẦN BẢO VỆ KL")),"") | K93: =IF(OR(ISNUMBER(F93),ISNUMBER(G93)),IF(ISBLANK(G93),"Kỹ sư/Thầu phụ cần bóc tách KL bản vẽ",IF(H93>=0,"Được đặt hàng tối đa "&G93&" "&E93,"Vượt dự toán "&ABS(H93)&" "&E93&" (QS giải trình & duyệt sửa BOQ)")),"")
A94: DHKK-A.I.2.46 | C94: NRD 200x300 | D94: Cái | E94: Cái | F94: 0 | G94: =F94 | H94: =IF(OR(ISNUMBER(F94),ISNUMBER(G94)),N(F94)-N(G94),"") | J94: =IF(OR(ISNUMBER(F94),ISNUMBER(G94)),IF(ISBLANK(G94),"⚠️ Chưa bóc tách định mức",IF(H94>=0,"✅ OK - Cho phép đặt hàng","❌ CHẶN ĐẶT HÀNG - CẦN BẢO VỆ KL")),"") | K94: =IF(OR(ISNUMBER(F94),ISNUMBER(G94)),IF(ISBLANK(G94),"Kỹ sư/Thầu phụ cần bóc tách KL bản vẽ",IF(H94>=0,"Được đặt hàng tối đa "&G94&" "&E94,"Vượt dự toán "&ABS(H94)&" "&E94&" (QS giải trình & duyệt sửa BOQ)")),"")
A95: DHKK-A.I.2.47 | C95: NRD 200x200 | D95: Cái | E95: Cái | F95: 1 | G95: =F95 | H95: =IF(OR(ISNUMBER(F95),ISNUMBER(G95)),N(F95)-N(G95),"") | J95: =IF(OR(ISNUMBER(F95),ISNUMBER(G95)),IF(ISBLANK(G95),"⚠️ Chưa bóc tách định mức",IF(H95>=0,"✅ OK - Cho phép đặt hàng","❌ CHẶN ĐẶT HÀNG - CẦN BẢO VỆ KL")),"") | K95: =IF(OR(ISNUMBER(F95),ISNUMBER(G95)),IF(ISBLANK(G95),"Kỹ sư/Thầu phụ cần bóc tách KL bản vẽ",IF(H95>=0,"Được đặt hàng tối đa "&G95&" "&E95,"Vượt dự toán "&ABS(H95)&" "&E95&" (QS giải trình & duyệt sửa BOQ)")),"")
A96: DHKK-A.I.2.48 | C96: NRD 200x150 | D96: Cái | E96: Cái | F96: 1 | G96: =F96 | H96: =IF(OR(ISNUMBER(F96),ISNUMBER(G96)),N(F96)-N(G96),"") | J96: =IF(OR(ISNUMBER(F96),ISNUMBER(G96)),IF(ISBLANK(G96),"⚠️ Chưa bóc tách định mức",IF(H96>=0,"✅ OK - Cho phép đặt hàng","❌ CHẶN ĐẶT HÀNG - CẦN BẢO VỆ KL")),"") | K96: =IF(OR(ISNUMBER(F96),ISNUMBER(G96)),IF(ISBLANK(G96),"Kỹ sư/Thầu phụ cần bóc tách KL bản vẽ",IF(H96>=0,"Được đặt hàng tối đa "&G96&" "&E96,"Vượt dự toán "&ABS(H96)&" "&E96&" (QS giải trình & duyệt sửa BOQ)")),"")
...
